Workbook
Name Slicer_Department: #N/A
Name Slicer_Employee_Name: #N/A
Name Slicer_Expense_Category: #N/A

Sheet Employee_Master Sheet
A1: Employee_ID | B1: Employee_Name | C1: Department
A2: E001 | B2: Rahul Sharma | C2: Sales
A3: E002 | B3: Neha Gupta | C3: Marketing
A4: E003 | B4: Arjun Verma | C4: Finance
A5: E004 | B5: Sonal Mehta | C5: HR
A6: E005 | B6: Aman Singh | C6: Operations
A7: E006 | B7: Riya Malhotra | C7: Sales
A8: E007 | B8: Karan Patel | C8: Finance
A9: E008 | B9: Pooja Nair | C9: HR
A10: E009 | B10: Rohan Iyer | C10: Sales
A11: E010 | B11: Nisha Jain | C11: Operations

Sheet Expense Raw Data
A1: Employee_ID | B1: Employee_Name | C1: Department | D1: Expense_Date | E1: Expense_Category | F1: Merchant | G1: Amount | H1: Bill_Attached | I1: Payment_Mode | J1: Policy_Limit | K1: Status | L1: Comments | M1: Policy_Violation | N1: Missing_Bill_Flag | O1: Cash_Payment_Flag | P1: Weekend_Expense_Flag | Q1: Final_Status
A2: E001 | B2: =VLOOKUP(A2,'Employee_Master Sheet'!$A$2:$B$11,2,FALSE) -> Rahul Sharma | C2: =VLOOKUP(A2,'Employee_Master Sheet'!$A$2:$C$11,3,FALSE) -> Sales | D2: 45659 | E2: Travel | F2: Uber | G2: 350 | H2: Yes | I2: Card | J2: 500 | K2: Pending | L2: - | M2: =IF(G2>J2,"Yes","No") -> No | N2: =IF(H2="No","Yes","No") -> No | O2: =IF(I2="Cash","Yes","No") -> No | P2: =IF(WEEKDAY(D2,2)>5,"Yes","No") -> No | Q2: =IF(OR(M2="Yes",N2="Yes",O2="Yes",P2="Yes"),"Review Required","Approved") -> Approved
A3: E002 | B3: =VLOOKUP(A3,'Employee_Master Sheet'!$A$2:$B$11,2,FALSE) -> Neha Gupta | C3: =VLOOKUP(A3,'Employee_Master Sheet'!$A$2:$C$11,3,FALSE) -> Marketing | D3: 45660 | E3: Meals | F3: Starbucks | G3: 750 | H3: No | I3: Cash | J3: 500 | K3: Pending | L3: - | M3: =IF(G3>J3,"Yes","No") -> Yes | N3: =IF(H3="No","Yes","No") -> Yes | O3: =IF(I3="Cash","Yes","No") -> Yes | P3: =IF(WEEKDAY(D3,2)>5,"Yes","No") -> No | Q3: =IF(OR(M3="Yes",N3="Yes",O3="Yes",P3="Yes"),"Review Required","Approved") -> Review Required
A4: E003 | B4: =VLOOKUP(A4,'Employee_Master Sheet'!$A$2:$B$11,2,FALSE) -> Arjun Verma | C4: =VLOOKUP(A4,'Employee_Master Sheet'!$A$2:$C$11,3,FALSE) -> Finance | D4: 45662 | E4: Stationery | F4: Amazon | G4: 1200 | H4: Yes | I4: Card | J4: 1000 | K4: Pending | L4: - | M4: =IF(G4>J4,"Yes","No") -> Yes | N4: =IF(H4="No","Yes","No") -> No | O4: =IF(I4="Cash","Yes","No") -> No | P4: =IF(WEEKDAY(D4,2)>5,"Yes","No") -> Yes | Q4: =IF(OR(M4="Yes",N4="Yes",O4="Yes",P4="Yes"),"Review Required","Approved") -> Review Required
A5: E001 | B5: =VLOOKUP(A5,'Employee_Master Sheet'!$A$2:$B$11,2,FALSE) -> Rahul Sharma | C5: =VLOOKUP(A5,'Employee_Master Sheet'!$A$2:$C$11,3,FALSE) -> Sales | D5: 45662 | E5: Meals | F5: KFC | G5: 600 | H5: Yes | I5: Card | J5: 500 | K5: Pending | L5: - | M5: =IF(G5>J5,"Yes","No") -> Yes | N5: =IF(H5="No","Yes","No") -> No | O5: =IF(I5="Cash","Yes","No") -> No | P5: =IF(WEEKDAY(D5,2)>5,"Yes","No") -> Yes | Q5: =IF(OR(M5="Yes",N5="Yes",O5="Yes",P5="Yes"),"Review Required","Approved") -> Review Required
A6: E004 | B6: =VLOOKUP(A6,'Employee_Master Sheet'!$A$2:$B$11,2,FALSE) -> Sonal Mehta | C6: =VLOOKUP(A6,'Employee_Master Sheet'!$A$2:$C$11,3,FALSE) -> HR | D6: 45665 | E6: Travel | F6: Uber | G6: 900 | H6: No | I6: Cash | J6: 500 | K6: Pending | L6: - | M6: =IF(G6>J6,"Yes","No") -> Yes | N6: =IF(H6="No","Yes","No") -> Yes | O6: =IF(I6="Cash","Yes","No") -> Yes | P6: =IF(WEEKDAY(D6,2)>5,"Yes","No") -> No | Q6: =IF(OR(M6="Yes",N6="Yes",O6="Yes",P6="Yes"),"Review Required","Approved") -> Review Required
A7: E005 | B7: =VLOOKUP(A7,'Employee_Master Sheet'!$A$2:$B$11,2,FALSE) -> Aman Singh | C7: =VLOOKUP(A7,'Employee_Master Sheet'!$A$2:$C$11,3,FALSE) -> Operations | D7: 45666 | E7: Travel | F7: Ola | G7: 450 | H7: Yes | I7: Card | J7: 500 | K7: Pending | L7: - | M7: =IF(G7>J7,"Yes","No") -> No | N7: =IF(H7="No","Yes","No") -> No | O7: =IF(I7="Cash","Yes","No") -> No | P7: =IF(WEEKDAY(D7,2)>5,"Yes","No") -> No | Q7: =IF(OR(M7="Yes",N7="Yes",O7="Yes",P7="Yes"),"Review Required","Approved") -> Approved
A8: E002 | B8: =VLOOKUP(A8,'Employee_Master Sheet'!$A$2:$B$11,2,FALSE) -> Neha Gupta | C8: =VLOOKUP(A8,'Employee_Master Sheet'!$A$2:$C$11,3,FALSE) -> Marketing | D8: 45667 | E8: Meals | F8: Subway | G8: 400 | H8: Yes | I8: Card | J8: 500 | K8: Pending | L8: - | M8: =IF(G8>J8,"Yes","No") -> No | N8: =IF(H8="No","Yes","No") -> No | O8: =IF(I8="Cash","Yes","No") -> No | P8: =IF(WEEKDAY(D8,2)>5,"Yes","No") -> No | Q8: =IF(OR(M8="Yes",N8="Yes",O8="Yes",P8="Yes"),"Review Required","Approved") -> Approved
A9: E006 | B9: =VLOOKUP(A9,'Employee_Master Sheet'!$A$2:$B$11,2,FALSE) -> Riya Malhotra | C9: =VLOOKUP(A9,'Employee_Master Sheet'!$A$2:$C$11,3,FALSE) -> Sales | D9: 45668 | E9: Client Meeting | F9: Taj Hotel | G9: 3200 | H9: Yes | I9: Card | J9: 3000 | K9: Pending | L9: - | M9: =IF(G9>J9,"Yes","No") -> Yes | N9: =IF(H9="No","Yes","No") -> No | O9: =IF(I9="Cash","Yes","No") -> No | P9: =IF(WEEKDAY(D9,2)>5,"Yes","No") -> Yes | Q9: =IF(OR(M9="Yes",N9="Yes",O9="Yes",P9="Yes"),"Review Required","Approved") -> Review Required
A10: E007 | B10: =VLOOKUP(A10,'Employee_Master Sheet'!$A$2:$B$11,2,FALSE) -> Karan Patel | C10: =VLOOKUP(A10,'Employee_Master Sheet'!$A$2:$C$11,3,FALSE) -> Finance | D10: 45669 | E10: Software | F10: Microsoft | G10: 4500 | H10: Yes | I10: Card | J10: 5000 | K10: Pending | L10: - | M10: =IF(G10>J10,"Yes","No") -> No | N10: =IF(H10="No","Yes","No") -> No | O10: =IF(I10="Cash","Yes","No") -> No | P10: =IF(WEEKDAY(D10,2)>5,"Yes","No") -> Yes | Q10: =IF(OR(M10="Yes",N10="Yes",O10="Yes",P10="Yes"),"Review Required","Approved") -> Review Required
A11: E003 | B11: =VLOOKUP(A11,'Employee_Master Sheet'!$A$2:$B$11,2,FALSE) -> Arjun Verma | C11: =VLOOKUP(A11,'Employee_Master Sheet'!$A$2:$C$11,3,FALSE) -> Finance | D11: 45670 | E11: Meals | F11: McDonalds | G11: 550 | H11: No | I11: Cash | J11: 500 | K11: Pending | L11: - | M11: =IF(G11>J11,"Yes","No") -> Yes | N11: =IF(H11="No","Yes","No") -> Yes | O11: =IF(I11="Cash","Yes","No") -> Yes | P11: =IF(WEEKDAY(D11,2)>5,"Yes","No") -> No | Q11: =IF(OR(M11="Yes",N11="Yes",O11="Yes",P11="Yes"),"Review Required","Approved") -> Review Required
A12: E008 | B12: =VLOOKUP(A12,'Employee_Master Sheet'!$A$2:$B$11,2,FALSE) -> Pooja Nair | C12: =VLOOKUP(A12,'Employee_Master Sheet'!$A$2:$C$11,3,FALSE) -> HR | D12: 45671 | E12: Travel | F12: Uber | G12: 200 | H12: Yes | I12: Card | J12: 500 | K12: Pending | L12: - | M12: =IF(G12>J12,"Yes","No") -> No | N12: =IF(H12="No","Yes","No") -> No | O12: =IF(I12="Cash","Yes","No") -> No | P12: =IF(WEEKDAY(D12,2)>5,"Yes","No") -> No | Q12: =IF(OR(M12="Yes",N12="Yes",O12="Yes",P12="Yes"),"Review Required","Approved") -> Approved
A13: E009 | B13: =VLOOKUP(A13,'Employee_Master Sheet'!$A$2:$B$11,2,FALSE) -> Rohan Iyer | C13: =VLOOKUP(A13,'Employee_Master Sheet'!$A$2:$C$11,3,FALSE) -> Sales | D13: 45672 | E13: Client Meeting | F13: BBQ Nation | G13: 2800 | H13: Yes | I13: Card | J13: 2500 | K13: Pending | L13: - | M13: =IF(G13>J13,"Yes","No") -> Yes | N13: =IF(H13="No","Yes","No") -> No | O13: =IF(I13="Cash","Yes","No") -> No | P13: =IF(WEEKDAY(D13,2)>5,"Yes","No") -> No | Q13: =IF(OR(M13="Yes",N13="Yes",O13="Yes",P13="Yes"),"Review Required","Approved") -> Review Required
... A31: E010 | B31: =VLOOKUP(A31,'Employee_Master Sheet'!$A$2:$B$11,2,FALSE) -> Nisha Jain | C31: =VLOOKUP(A31,'Employee_Master Sheet'!$A$2:$C$11,3,FALSE) -> Operations | D31: 45688 | E31: Travel | F31: Ola | G31: 480 | H31: Yes | I31: Card | J31: 500 | K31: Pending | L31: - | M31: =IF(G31>J31,"Yes","No") -> No | N31: =IF(H31="No","Yes","No") -> No | O31: =IF(I31="Cash","Yes","No") -> No | P31: =IF(WEEKDAY(D31,2)>5,"Yes","No") -> No | Q31: =IF(OR(M31="Yes",N31="Yes",O31="Yes",P31="Yes"),"Review Required","Approved") -> Approved

Sheet Summary
A2: Approval Status | G2: Top Employees by Spend
A3: Row Labels | B3: Number of Expenses | G3: Row Labels | H3: Sum of Amount
A4: Approved | B4: 9 | G4: Rohan Iyer | H4: 8320
A5: Review Required | B5: 21 | G5: Karan Patel | H5: 5550
A6: Grand Total | B6: 30 | G6: Neha Gupta | H6: 5350
G7: Riya Malhotra | H7: 4550
A8: Policy Violations by Department | G8: Aman Singh | H8: 2850
A9: Policy_Violation | B9: Yes | G9: Arjun Verma | H9: 2050
G10: Nisha Jain | H10: 1980
A11: Row Labels | B11: Count of Policy_Violation | G11: Sonal Mehta | H11: 1750
A12: Finance | B12: 3 | G12: Rahul Sharma | H12: 1430
A13: HR | B13: 3 | G13: Pooja Nair | H13: 1170
A14: Marketing | B14: 2 | G14: Grand Total | H14: 35000
A15: Operations | B15: 3
A16: Sales | B16: 7
A17: Grand Total | B17: 18
A19: Cash Payments by Department
A20: Cash_Payment_Flag | B20: Yes
A22: Row Labels | B22: Count of Cash_Payment_Flag
A23: Finance | B23: 1
A24: HR | B24: 2
A25: Marketing | B25: 1
A26: Operations | B26: 1
A27: Sales | B27: 1
A28: Grand Total | B28: 6

Sheet Dashboard
D2: EXPENSE DASHBOARD
B4: Total Expenses | D4: Policy Violations | F4: Cash Payments | H4: Weekend Expenses
B5: =SUM(Table2[Amount]) -> 35000 | D5: =GETPIVOTDATA("Policy_Violation",$F$56) -> 18 | F5: =COUNTIF(Table2[Cash_Payment_Flag],"Yes") -> 6 | H5: =COUNTIF(Table2[Weekend_Expense_Flag],"yes") -> 8
B53: Approval Status | F53: Policy Violations by Department
B54: Row Labels | C54: Number of Expenses | F54: Policy_Violation | G54: Yes
B55: Approved | C55: 9
B56: Review Required | C56: 21 | F56: Row Labels | G56: Count of Policy_Violation
B57: Grand Total | C57: 30 | F57: Finance | G57: 3
F58: HR | G58: 3
F59: Marketing | G59: 2
F60: Operations | G60: 3
F61: Sales | G61: 7
F62: Grand Total | G62: 18
B64: Cash Payments by Department | F64: Top Employees by Spend
B65: Cash_Payment | C65: Yes | F65: Row Labels | G65: Sum of Amount
F66: Rohan Iyer | G66: 8320
B67: Row Labels | C67: Count of Cash_Payment | F67: Karan Patel | G67: 5550
B68: Finance | C68: 1 | F68: Neha Gupta | G68: 5350
B69: HR | C69: 2 | F69: Riya Malhotra | G69: 4550
B70: Marketing | C70: 1 | F70: Aman Singh | G70: 2850
B71: Operations | C71: 1 | F71: Arjun Verma | G71: 2050
B72: Sales | C72: 1 | F72: Nisha Jain | G72: 1980
B73: Grand Total | C73: 6 | F73: Sonal Mehta | G73: 1750
F74: Rahul Sharma | G74: 1430
F75: Pooja Nair | G75: 1170
F76: Grand Total | G76: 35000
B78: Category Breakdown | F78: Trend Over Time
B79: Row Labels | C79: Sum of Amount | F79: Row Labels | G79: Sum of Amount
B80: Client Meeting | C80: 15200 | F80: 45659 | G80: 350
B81: Meals | C81: 5370 | F81: 45660 | G81: 750
B82: Software | C82: 4500 | F82: 45662 | G82: 1800
B83: Stationery | C83: 3350 | F83: 45665 | G83: 900
B84: Travel | C84: 6580 | F84: 45666 | G84: 450
B85: Grand Total | C85: 35000 | F85: 45667 | G85: 400
F86: 45668 | G86: 3200
F87: 45669 | G87: 4500
F88: 45670 | G88: 550
F89: 45671 | G89: 200
F90: 45672 | G90: 2800
F91: 45673 | G91: 850
...
